<?xml version="1.0" ?>
<robot name="robotic_arm" xmlns:xacro="http://www.ros.org/wiki/xacro">

<xacro:arg name="use_gazebo" default="false" />

<xacro:include filename="$(find robotic_arm_description)/urdf/materials.xacro" />

<!-- Only include Gazebo ros2_control and physics overrides if we are specifically launching it -->
<xacro:if value="$(arg use_gazebo)">
  <xacro:include filename="$(find robotic_arm_description)/urdf/robotic_arm.trans" />
  <xacro:include filename="$(find robotic_arm_description)/urdf/robotic_arm.gazebo" />
</xacro:if>

<link name="base_link">
  <inertial>
    <origin xyz="-0.0004708423328156958 -0.010037624526809919 0.033163866275274546" rpy="0 0 0"/>
    <mass value="0.5814746369835415"/>
    <inertia ixx="0.000512" iyy="0.00048" izz="0.000439" ixy="-3e-06" iyz="0.000104" ixz="4e-06"/>
  </inertial>
  <visual>
    <origin xyz="0 0 0" rpy="0 0 0"/>
    <geometry>
      <mesh filename="package://robotic_arm_description/meshes/base_link.stl" scale="0.001 0.001 0.001"/>
    </geometry>
    <material name="silver"/>
  </visual>
  <collision>
    <origin xyz="0 0 0" rpy="0 0 0"/>
    <geometry>
      <mesh filename="package://robotic_arm_description/meshes/base_link.stl" scale="0.001 0.001 0.001"/>
    </geometry>
  </collision>
</link>

<link name="link_1_1">
  <inertial>
    <origin xyz="0.00727320881418132 -9.695033510196543e-05 0.01256393012754363" rpy="0 0 0"/>
    <mass value="0.2996131685966876"/>
    <inertia ixx="6e-05" iyy="5.5e-05" izz="8.8e-05" ixy="1e-06" iyz="0.0" ixz="-2e-06"/>
  </inertial>
  <visual>
    <origin xyz="-0.0 0.029745 -0.0771" rpy="0 0 0"/>
    <geometry>
      <mesh filename="package://robotic_arm_description/meshes/link_1_1.stl" scale="0.001 0.001 0.001"/>
    </geometry>
    <material name="silver"/>
  </visual>
  <collision>
    <origin xyz="-0.0 0.029745 -0.0771" rpy="0 0 0"/>
    <geometry>
      <mesh filename="package://robotic_arm_description/meshes/link_1_1.stl" scale="0.001 0.001 0.001"/>
    </geometry>
  </collision>
</link>

<link name="link_2_1">
  <inertial>
    <origin xyz="-0.023152965047785325 6.387036229071885e-07 0.055246710197775814" rpy="0 0 0"/>
    <mass value="0.14325214411599796"/>
    <inertia ixx="0.00017" iyy="0.000244" izz="8.9e-05" ixy="-0.0" iyz="-0.0" ixz="0.0"/>
  </inertial>
  <visual>
    <origin xyz="-0.0336 0.039745 -0.090845" rpy="0 0 0"/>
    <geometry>
      <mesh filename="package://robotic_arm_description/meshes/link_2_1.stl" scale="0.001 0.001 0.001"/>
    </geometry>
    <material name="silver"/>
  </visual>
  <collision>
    <origin xyz="-0.0336 0.039745 -0.090845" rpy="0 0 0"/>
    <geometry>
      <mesh filename="package://robotic_arm_description/meshes/link_2_1.stl" scale="0.001 0.001 0.001"/>
    </geometry>
  </collision>
</link>

<link name="link_3_1">
  <inertial>
    <origin xyz="-0.025678377520148184 -0.055313925153009674 -0.0012497479581907167" rpy="0 0 0"/>
    <mass value="0.6861400527625597"/>
    <inertia ixx="0.002715" iyy="0.000118" izz="0.002771" ixy="1e-06" iyz="0.0" ixz="-1e-06"/>
  </inertial>
  <visual>
    <origin xyz="-0.0336 0.039743 -0.201338" rpy="0 0 0"/>
    <geometry>
      <mesh filename="package://robotic_arm_description/meshes/link_3_1.stl" scale="0.001 0.001 0.001"/>
    </geometry>
    <material name="silver"/>
  </visual>
  <collision>
    <origin xyz="-0.0336 0.039743 -0.201338" rpy="0 0 0"/>
    <geometry>
      <mesh filename="package://robotic_arm_description/meshes/link_3_1.stl" scale="0.001 0.001 0.001"/>
    </geometry>
  </collision>
</link>

<link name="link_4_1">
  <inertial>
    <origin xyz="-0.02448467338761244 -0.04159904203161033 1.0463502536361968e-06" rpy="0 0 0"/>
    <mass value="0.3128832689944911"/>
    <inertia ixx="9.2e-05" iyy="8.5e-05" izz="0.000154" ixy="-5e-06" iyz="0.0" ixz="0.0"/>
  </inertial>
  <visual>
    <origin xyz="-0.033601 0.170236 -0.201338" rpy="0 0 0"/>
    <geometry>
      <mesh filename="package://robotic_arm_description/meshes/link_4_1.stl" scale="0.001 0.001 0.001"/>
    </geometry>
    <material name="silver"/>
  </visual>
  <collision>
    <origin xyz="-0.033601 0.170236 -0.201338" rpy="0 0 0"/>
    <geometry>
      <mesh filename="package://robotic_arm_description/meshes/link_4_1.stl" scale="0.001 0.001 0.001"/>
    </geometry>
  </collision>
</link>

<link name="link_5_1">
  <inertial>
    <origin xyz="-0.021636966993527323 -0.024386440293857586 -0.01952781494223152" rpy="0 0 0"/>
    <mass value="0.31108337630150573"/>
    <inertia ixx="8.2e-05" iyy="0.000125" izz="8.6e-05" ixy="-6e-06" iyz="-5e-06" ixz="-1.9e-05"/>
  </inertial>
  <visual>
    <origin xyz="-0.018601 0.240982 -0.201339" rpy="0 0 0"/>
    <geometry>
      <mesh filename="package://robotic_arm_description/meshes/link_5_1.stl" scale="0.001 0.001 0.001"/>
    </geometry>
    <material name="silver"/>
  </visual>
  <collision>
    <origin xyz="-0.018601 0.240982 -0.201339" rpy="0 0 0"/>
    <geometry>
      <mesh filename="package://robotic_arm_description/meshes/link_5_1.stl" scale="0.001 0.001 0.001"/>
    </geometry>
  </collision>
</link>

<link name="Gripper_Link_v1__1__1">
  <inertial>
    <origin xyz="1.2271797061175205e-07 -0.014999757000281333 0.0012500652966639658" rpy="0 0 0"/>
    <mass value="0.0026001888529129063"/>
    <inertia
      ixx="8.67e-7"
      iyy="8.67e-7"
      izz="3.47e-7"
      ixy="0"
      iyz="0"
      ixz="0"/>
  </inertial>
  <visual>
    <origin xyz="-0.023127 0.286587 -0.205839" rpy="0 0 0"/>
    <geometry>
      <mesh filename="package://robotic_arm_description/meshes/Gripper_Link_v1__1__1.stl" scale="0.001 0.001 0.001"/>
    </geometry>
    <material name="silver"/>
  </visual>
  <collision>
    <origin xyz="-0.023127 0.286587 -0.205839" rpy="0 0 0"/>
    <geometry>
      <mesh filename="package://robotic_arm_description/meshes/Gripper_Link_v1__1__1.stl" scale="0.001 0.001 0.001"/>
    </geometry>
  </collision>
</link>

<link name="Gripper_Link_v1_1">
  <inertial>
    <origin xyz="-1.743690654504304e-07 -0.01500006032999912 0.0012500652966641879" rpy="0 0 0"/>
    <mass value="0.0026001888529129063"/>
    <inertia
      ixx="1e-7"
      iyy="1e-7"
      izz="1e-7"
      ixy="0"
      iyz="0"
      ixz="0"/>
  </inertial>
  <visual>
    <origin xyz="-0.014122 0.286592 -0.205839" rpy="0 0 0"/>
    <geometry>
      <mesh filename="package://robotic_arm_description/meshes/Gripper_Link_v1_1.stl" scale="0.001 0.001 0.001"/>
    </geometry>
    <material name="silver"/>
  </visual>
  <collision>
    <origin xyz="-0.014122 0.286592 -0.205839" rpy="0 0 0"/>
    <geometry>
      <mesh filename="package://robotic_arm_description/meshes/Gripper_Link_v1_1.stl" scale="0.001 0.001 0.001"/>
    </geometry>
  </collision>
</link>

<link name="GripperFinger_1">
  <inertial>
    <origin xyz="-0.004012064636261022 0.0022123496307863144 -0.002999934703335788" rpy="0 0 0"/>
    <mass value="0.023268782295470917"/>
    <inertia ixx="7e-06" iyy="1e-06" izz="7e-06" ixy="1e-06" iyz="0.0" ixz="-0.0"/>
  </inertial>
  <visual>
    <origin xyz="-0.014122 0.316592 -0.205839" rpy="0 0 0"/>
    <geometry>
      <mesh filename="package://robotic_arm_description/meshes/GripperFinger_1.stl" scale="0.001 0.001 0.001"/>
    </geometry>
    <material name="silver"/>
  </visual>
  <collision>
    <origin xyz="-0.014122 0.316592 -0.205839" rpy="0 0 0"/>
    <geometry>
      <mesh filename="package://robotic_arm_description/meshes/GripperFinger_1.stl" scale="0.001 0.001 0.001"/>
    </geometry>
  </collision>
</link>

<link name="GripperFinger2_1">
  <inertial>
    <origin xyz="0.0040120129851667526 0.0022126529605374645 -0.00299993470333626" rpy="0 0 0"/>
    <mass value="0.02326878229547092"/>
    <inertia ixx="7e-06" iyy="1e-06" izz="7e-06" ixy="-1e-06" iyz="0.0" ixz="-0.0"/>
  </inertial>
  <visual>
    <origin xyz="-0.023127 0.316587 -0.205839" rpy="0 0 0"/>
    <geometry>
      <mesh filename="package://robotic_arm_description/meshes/GripperFinger2_1.stl" scale="0.001 0.001 0.001"/>
    </geometry>
    <material name="silver"/>
  </visual>
  <collision>
    <origin xyz="-0.023127 0.316587 -0.205839" rpy="0 0 0"/>
    <geometry>
      <mesh filename="package://robotic_arm_description/meshes/GripperFinger2_1.stl" scale="0.001 0.001 0.001"/>
    </geometry>
  </collision>
</link>

<link name="Gripper_Link_Gear#1_v1_1">
  <inertial>
    <origin xyz="0.00017270546084355298 -0.006692594476805369 0.0012500652966642989" rpy="0 0 0"/>
    <mass value="0.01465980896634144"/>
    <inertia ixx="2e-06" iyy="1e-06" izz="3e-06" ixy="0.0" iyz="0.0" ixz="0.0"/>
  </inertial>
  <visual>
    <origin xyz="-0.03193 0.266281 -0.205839" rpy="0 0 0"/>
    <geometry>
      <mesh filename="package://robotic_arm_description/meshes/gripper_link_gear1_v1_1.stl" scale="0.001 0.001 0.001"/>
    </geometry>
    <material name="silver"/>
  </visual>
  <collision>
    <origin xyz="-0.03193 0.266281 -0.205839" rpy="0 0 0"/>
    <geometry>
      <mesh filename="package://robotic_arm_description/meshes/gripper_link_gear1_v1_1.stl" scale="0.001 0.001 0.001"/>
    </geometry>
  </collision>
</link>

<joint name="link_1" type="revolute">
  <limit lower="-3.14159" upper="3.14159" effort="100.0" velocity="1.0"/>
  <origin xyz="0.0 -0.029745 0.0771" rpy="0 0 0"/>
  <parent link="base_link"/>
  <child link="link_1_1"/>
  <axis xyz="0.0 -0.0 1.0"/>
</joint>


<joint name="link_2" type="revolute">
  <limit lower="-3.14159" upper="3.14159" effort="100.0" velocity="1.0"/>
  <origin xyz="0.0336 -0.01 0.013745" rpy="0 0 0"/>
  <parent link="link_1_1"/>
  <child link="link_2_1"/>
  <axis xyz="1.0 0.0 0.0"/>
</joint>


<joint name="link_3" type="revolute">
  <limit lower="-3.14159" upper="3.14159" effort="100.0" velocity="1.0"/>
  <origin xyz="0.0 2e-06 0.110493" rpy="0 0 0"/>
  <parent link="link_2_1"/>
  <child link="link_3_1"/>
  <axis xyz="-1.0 -0.0 -0.0"/>
</joint>


<joint name="link_4" type="revolute">
  <limit lower="-3.14159" upper="3.14159" effort="100.0" velocity="1.0"/>
  <origin xyz="1e-06 -0.130493 0.0" rpy="0 0 0"/>
  <parent link="link_3_1"/>
  <child link="link_4_1"/>
  <axis xyz="1.0 -0.0 0.0"/>
</joint>


<joint name="link_5" type="revolute">
  <limit lower="-3.14159" upper="3.14159" effort="100.0" velocity="1.0"/>
  <origin xyz="-0.015 -0.070746 1e-06" rpy="0 0 0"/>
  <parent link="link_4_1"/>
  <child link="link_5_1"/>
  <axis xyz="0.0 -1.0 -0.0"/>
</joint>


<joint name="link_6" type="revolute">
  <origin xyz="0.013329 -0.025299 0.0045" rpy="0 0 0"/>
  <parent link="link_5_1"/>
  <child link="Gripper_Link_Gear#1_v1_1"/>
  <axis xyz="-0.0 0.0 1.0"/>
  <limit lower="-1.0" upper="1.0" effort="10.0" velocity="0.5"/>
</joint>

<joint name="link_10" type="continuous">
  <origin xyz="0.004526 -0.045605 0.0045" rpy="0 0 0"/>
  <parent link="link_5_1"/>
  <child link="Gripper_Link_v1__1__1"/>
  <axis xyz="0.0 -0.0 -1.0"/>
  <mimic joint = "link_6" multiplier="-1"/>
</joint>

<joint name="link_11" type="continuous">
  <origin xyz="-0.004479 -0.04561 0.0045" rpy="0 0 0"/>
  <parent link="link_5_1"/>
  <child link="Gripper_Link_v1_1"/>
  <axis xyz="0.0 -0.0 -1.0"/>
  <mimic joint = "link_6" multiplier="1"/>
</joint>

<joint name="link_12" type="continuous">
  <origin xyz="0.0 -0.03 0.0" rpy="0 0 0"/>
  <parent link="Gripper_Link_v1_1"/>
  <child link="GripperFinger_1"/>
  <axis xyz="-0.0 0.0 1.0"/>
  <mimic joint = "link_6" multiplier="1"/>
</joint>

<joint name="link_13" type="continuous">
  <origin xyz="0.0 -0.03 0.0" rpy="0 0 0"/>
  <parent link="Gripper_Link_v1__1__1"/>
  <child link="GripperFinger2_1"/>
  <axis xyz="-0.0 -0.0 1.0"/>
  <mimic joint = "link_6" multiplier="-1"/>
</joint>

</robot>